Workbook

Sheet Guide
A1: 단계 | B1: 가이드
A2: 1 | B2: Source Check에서 소스 단위로 상태를 체크하세요.
A3: 2 | B3: Item Audit에서 각 항목 바로 옆 체크칸(landing/title/description/thumbnail)을 채우세요.
A4: 3 | B4: source_review_status는 Source Check 상태를 자동 참조합니다.

Sheet Source Check
A1: review_status | B1: source_id | C1: source_name | D1: source_url | E1: source_check | F1: landing_check | G1: thumbnail_check | H1: title_check | I1: description_check | J1: source_issue_notes | K1: source_active | L1: source_level | M1: source_added_at | N1: item_count | O1: exposed_item_count | P1: memo_item_count | Q1: latest_exposed_date
A2: 미확인 | B2: 62 | C2: generalist.com | D2: https://www.generalist.com/ | K2: 1 | L2: core | M2: 2026-04-15 06:31:36 | N2: 21 | O2: 3 | P2: 0 | Q2: 2026-04-19
A3: 미확인 | B3: 63 | C3: bucketplace.com | D3: https://www.bucketplace.com/culture/ | K3: 1 | L3: light | M3: 2026-04-15 06:31:36 | N3: 19 | O3: 1 | P3: 0 | Q3: 2026-04-18
A4: 미확인 | B4: 61 | C4: techblog.gccompany.co.kr | D4: https://techblog.gccompany.co.kr/ | K4: 1 | L4: focus | M4: 2026-04-15 06:31:35 | N4: 11 | O4: 0 | P4: 0
A5: 미확인 | B5: 59 | C5: intercom.com | D5: https://www.intercom.com/blog/ | K5: 1 | L5: focus | M5: 2026-04-15 06:31:34 | N5: 16 | O5: 0 | P5: 0
A6: 미확인 | B6: 58 | C6: uxdesign.cc | D6: https://uxdesign.cc/ | K6: 1 | L6: focus | M6: 2026-04-15 06:31:33 | N6: 11 | O6: 0 | P6: 0
A7: 미확인 | B7: 57 | C7: apple.com | D7: https://www.apple.com/kr/newsroom/ | K7: 1 | L7: focus | M7: 2026-04-15 06:31:33 | N7: 19 | O7: 0 | P7: 0
A8: 미확인 | B8: 56 | C8: newsroom.spotify.com | D8: https://newsroom.spotify.com/ | K8: 1 | L8: focus | M8: 2026-04-15 06:31:32 | N8: 11 | O8: 0 | P8: 0
A9: 미확인 | B9: 55 | C9: figma.com | D9: https://www.figma.com/blog/ | K9: 1 | L9: focus | M9: 2026-04-15 06:31:32 | N9: 19 | O9: 1 | P9: 0 | Q9: 2026-04-18
A10: 미확인 | B10: 54 | C10: thegradient.pub | D10: https://thegradient.pub/ | K10: 1 | L10: focus | M10: 2026-04-15 06:31:31 | N10: 16 | O10: 0 | P10: 0
A11: 미확인 | B11: 53 | C11: stratechery.com | D11: https://stratechery.com/ | K11: 1 | L11: focus | M11: 2026-04-15 06:31:31 | N11: 122 | O11: 10 | P11: 0 | Q11: 2026-04-19
A12: 미확인 | B12: 111 | C12: the-reader.or.kr | D12: https://www.the-reader.or.kr/ | K12: 1 | L12: light | M12: 2026-04-15 06:31:30 | N12: 1 | O12: 0 | P12: 0
A13: 미확인 | B13: 51 | C13: about.daangn.com | D13: https://about.daangn.com/blog/ | K13: 1 | L13: focus | M13: 2026-04-15 06:31:30 | N13: 22 | O13: 0 | P13: 0
A14: 미확인 | B14: 49 | C14: techcrunch.com | D14: https://techcrunch.com/ | K14: 1 | L14: focus | M14: 2026-04-15 06:31:29 | N14: 99 | O14: 10 | P14: 0 | Q14: 2026-04-17
A15: 미확인 | B15: 50 | C15: gcoo.io | D15: https://gcoo.io/en/blog | K15: 1 | L15: focus | M15: 2026-04-15 06:31:29 | N15: 19 | O15: 1 | P15: 0 | Q15: 2026-04-15
A16: 미확인 | B16: 48 | C16: toss.im | D16: https://toss.im/tossfeed | K16: 1 | L16: focus | M16: 2026-04-15 06:31:28 | N16: 52 | O16: 10 | P16: 0 | Q16: 2026-04-18
A17: 미확인 | B17: 47 | C17: medium.com | D17: https://medium.com/29cm | K17: 1 | L17: focus | M17: 2026-04-15 06:31:28 | N17: 11 | O17: 0 | P17: 0
A18: 미확인 | B18: 46 | C18: growth.design | D18: https://growth.design/ | K18: 1 | L18: focus | M18: 2026-04-15 06:31:27 | N18: 1 | O18: 0 | P18: 0
A19: 미확인 | B19: 44 | C19: producthunt.com | D19: https://www.producthunt.com/ | K19: 1 | L19: focus | M19: 2026-04-15 06:31:26 | N19: 110 | O19: 3 | P19: 0 | Q19: 2026-04-12
A20: 미확인 | B20: 45 | C20: jayoung.blog | D20: https://jayoung.blog/about | K20: 1 | L20: focus | M20: 2026-04-15 06:31:26 | N20: 21 | O20: 2 | P20: 1 | Q20: 2026-04-17
A21: 미확인 | B21: 43 | C21: plus.hankyung.com | D21: https://plus.hankyung.com/ | K21: 1 | L21: focus | M21: 2026-04-15 06:31:25 | N21: 39 | O21: 0 | P21: 0
A22: 미확인 | B22: 42 | C22: innoforest.co.kr | D22: https://www.innoforest.co.kr/report | K22: 1 | L22: light | M22: 2026-04-15 06:31:25 | N22: 1 | O22: 0 | P22: 0
A23: 미확인 | B23: 100 | C23: nngroup.com | D23: https://www.nngroup.com/ | K23: 1 | L23: focus | M23: 2026-04-15 06:31:24 | N23: 2 | O23: 2 | P23: 0 | Q23: 2026-04-17
A24: 미확인 | B24: 40 | C24: latpeed.com | D24: https://www.latpeed.com/ | K24: 1 | L24: light | M24: 2026-04-15 06:31:23 | N24: 1 | O24: 0 | P24: 0
A25: 미확인 | B25: 64 | C25: designboom.com | D25: https://www.designboom.com/ | K25: 1 | L25: core | M25: 2026-04-15 06:31:23 | N25: 20 | O25: 0 | P25: 0
A26: 미확인 | B26: 37 | C26: outstanding.kr | D26: https://outstanding.kr/search_detail/Ui%20%EC%A0%80%EC%9E%91%EA%B6%8C | K26: 1 | L26: focus | M26: 2026-04-15 06:31:22 | N26: 30 | O26: 3 | P26: 0 | Q26: 2026-04-12
A27: 미확인 | B27: 38 | C27: newneek.co | D27: https://newneek.co/ | K27: 1 | L27: core | M27: 2026-04-15 06:31:22 | N27: 62 | O27: 1 | P27: 0 | Q27: 2026-04-19
A28: 미확인 | B28: 36 | C28: longblack.co | D28: https://longblack.co/ | K28: 1 | L28: focus | M28: 2026-04-15 06:31:21 | N28: 45 | O28: 4 | P28: 0 | Q28: 2026-04-15

Sheet Item Audit
A1: review_status | B1: source_review_status | C1: source_id | D1: source_name | E1: source_url | F1: source_check | G1: item_id | H1: item_url | I1: landing_check | J1: title | K1: title_check | L1: summary | M1: description_check | N1: thumbnail_url | O1: thumbnail_check | P1: issue_category | Q1: fix_priority | R1: issue_notes | S1: source_active | T1: source_level | U1: source_added_at | V1: item_status | W1: exposure_count | X1: first_exposed_date | Y1: last_exposed_date | Z1: seen_since_2026_04_01 | AA1: has_note | AB1: note_updated_at | AC1: split_items | AD1: extraction_mode | AE1: landing_suspect | AF1: thumb_suspect | AG1: title_suspect | AH1: summary_suspect
A2: 미확인 | B2: =IFERROR(INDEX('Source Check'!$A:$A, MATCH(C2, 'Source Check'!$B:$B, 0)), "미등록") | C2: 62 | D2: generalist.com | E2: https://www.generalist.com/ | F2: =IFERROR(INDEX('Source Check'!$E:$E, MATCH(C2, 'Source Check'!$B:$B, 0)), "") | G2: 7907 | H2: https://www.generalist.com/ | J2: generalist.com | S2: 1 | T2: core | U2: 2026-04-15 06:31:36 | V2: active | W2: 0 | Z2: 0 | AA2: 0 | AC2: 0 | AE2: 0 | AF2: 1 | AG2: 1 | AH2: 1
A3: 미확인 | B3: =IFERROR(INDEX('Source Check'!$A:$A, MATCH(C3, 'Source Check'!$B:$B, 0)), "미등록") | C3: 62 | D3: generalist.com | E3: https://www.generalist.com/ | F3: =IFERROR(INDEX('Source Check'!$E:$E, MATCH(C3, 'Source Check'!$B:$B, 0)), "") | G3: 7714 | H3: https://www.generalist.com/p/54-books-to-read-in-2026 | J3: 54 books to read in 2026 | L3: Essential recommendations from some of the world's most interesting and accomplished people. | N3: https://substackcdn.com/image/fetch/$s_!OT6u!,f_auto,q_auto:good,fl_progressive:steep/https%3A%2F%2Fsubstack-post-media.s3.amazonaws.com%2Fpublic%2Fimages%2F4261ef09-5730-411d-8e39-ba88e4309d17_3200x1792.jpeg | S3: 1 | T3: core | U3: 2026-04-15 06:31:36 | V3: active | W3: 1 | X3: 2026-04-14 | Y3: 2026-04-14 | Z3: 1 | AA3: 0 | AC3: 0 | AE3: 0 | AF3: 0 | AG3: 0 | AH3: 0
A4: 미확인 | B4: =IFERROR(INDEX('Source Check'!$A:$A, MATCH(C4, 'Source Check'!$B:$B, 0)), "미등록") | C4: 62 | D4: generalist.com | E4: https://www.generalist.com/ | F4: =IFERROR(INDEX('Source Check'!$E:$E, MATCH(C4, 'Source Check'!$B:$B, 0)), "") | G4: 7695 | H4: https://www.generalist.com/p/how-a-20-person-startup-won-gold | J4: how a 20 person startup won gold | L4: Listen now | Tudor Achim explains how Harmonic built the world's first AI that produces formally verified outputs, why hallucinations drive creativity, and what happens when AI surpasses human mathematicians. | N4: https://substackcdn.com/image/fetch/$s_!S8uR!,w_1456,c_limit,f_auto,q_auto:good,fl_progressive:steep/https%3A%2F%2Fsubstack-post-media.s3.amazonaws.com%2Fpublic%2Fimages%2Fc3eb8b6f-d22b-42b4-8778-e726fbba7e39_1600x128.png | S4: 1 | T4: core | U4: 2026-04-15 06:31:36 | V4: active | W4: 1 | X4: 2026-04-13 | Y4: 2026-04-13 | Z4: 1 | AA4: 0 | AC4: 0 | AE4: 0 | AF4: 0 | AG4: 0 | AH4: 0
A5: 미확인 | B5: =IFERROR(INDEX('Source Check'!$A:$A, MATCH(C5, 'Source Check'!$B:$B, 0)), "미등록") | C5: 62 | D5: generalist.com | E5: https://www.generalist.com/ | F5: =IFERROR(INDEX('Source Check'!$E:$E, MATCH(C5, 'Source Check'!$B:$B, 0)), "") | G5: 360 | H5: https://www.generalist.com/p/why-being-a-generalist-vc-is-a-competitive-advantage | J5: Why Being a Generalist VC Is a Competitive Advantage | Aydin Senkut (Founder and Managing Partner at Felicis Ventures) | L5: Listen now | Felicis Ventures founder Aydin Senkut on how he built a top VC firm, his 10x decision framework, and why he's bullish on AI and automation. | N5: https://substackcdn.com/image/fetch/$s_!MFXo!,w_1456,c_limit,f_auto,q_auto:good,fl_progressive:steep/https%3A%2F%2Fsubstack-post-media.s3.amazonaws.com%2Fpublic%2Fimages%2F4d31932a-59f3-4e45-b41d-3c9b962b58b5_475x151.png | S5: 1 | T5: core | U5: 2026-04-15 06:31:36 | V5: active | W5: 0 | Z5: 0 | AA5: 0 | AC5: 0 | AE5: 0 | AF5: 0 | AG5: 0 | AH5: 0
A6: 미확인 | B6: =IFERROR(INDEX('Source Check'!$A:$A, MATCH(C6, 'Source Check'!$B:$B, 0)), "미등록") | C6: 62 | D6: generalist.com | E6: https://www.generalist.com/ | F6: =IFERROR(INDEX('Source Check'!$E:$E, MATCH(C6, 'Source Check'!$B:$B, 0)), "") | G6: 359 | H6: https://www.generalist.com/p/steve-case | J6: steve case | L6: Illustration by Eleanor Taylor Friends, Perhaps no one experienced the dotcom boom and bust quite as viscerally as Steve Case. The founder of Revolution began the decade as an executive at a small software company called Quantum Link, and ended it as the CEO of a behemoth: AOL. It is hard to overstate just how important a company AOL was at the start of the millennium. Unless you were already of working age and minded towards tech and business, there's a good chance you haven't calibrated its size appropriately. AOL was a giant. Between its IPO in 1992 and the start of the new millennium, its stock appreciated approximately 80,000% , reaching a peak of $222 billion in December 1999. By that point, it had eclipsed many of the business world's biggest companies, surpassing Disney, IBM, McDonald's, and Berkshire Hathaway. At the time, AOL was larger than Boeing and General Motors combined . It was also wildly significant and influential, responsible for opening the internet up to a new generation of users and making it fun to use. The AOL of that era pioneered many of the user experiences and behaviors that make up the modern web, from screen names to instant messaging. In January 2000, AOL looked set for another decade of dominance. On the tenth of that month, it announced a planned merger with Time Warner. Remarkably, AOL was the senior partner, receiving 55% of the combined $350 billion entity. Again, the scale of the deal is hard to comprehend unless you lived it. At the headline valuation, AOL Time Warner became the fourth largest company on the planet - a figure greater than "the output of Russia or the Netherlands." What came after is the subject of much study and coverage. The market crashed, the merger failed, and not long after, Case stepped down as AOL CEO. By 2005, Case publicly argued in favor of the two companies splitting, and at the end of the decade, that came to fruition. Though there were strong strategic merits to an AOL-Time Warner union, it proved to be a marriage that suited neither party. It seems as if we are in yet another torrid cycle and potentially one of greater magnitude than that which Case surfed. A recent analyst report argued that the current AI bubble is 17x greater than its dotcom corollary, and 4x larger than the 2008 financial crisis. (We can hope it will be more productive than the financial crash, at least.) A bubble is a strange environment in which to live. It is an even stranger one in which to build a business. How do you keep your feet on the ground when the world beneath is rushing past at a thousand miles an hour? How can you hold fast to reality when wide-eyed investors, gasping for breath, paint ever more fantastical futures in front of you and shove your pockets full of cash? Where is the boundary? Is there really such a thing as a horizon? We believe that "this time is different," and there is truth in that. We do not live in a perfectly iterated game. The board has changed, fresh players have stepped onto it, and new moves are always being invented. But it is more naive to pretend the past has nothing to teach us. In fundamental ways, today's founders face the same set of challenges as their late 90s forerunners. How do you build a team at warp speed? Is it possible to scale a culture when you're growing exponentially? How can you make smart acquisitions and avoid the most common missteps? What role should partnerships and business development play when you're forging a new category? As I thought about these questions, I realized that perhaps no one is better suited to speak from experience than Steve Case himself. And so, I asked him to reflect on his journey at AOL, the similarities and differences between that era and ours, and the lessons founders should heed. We also discuss what it was like to compete head-to-head against Bill Gates, the strategic necessity that drove the Time Warner deal, and the similarities between Jeff Bezos and Steve Jobs. Subscribe now Brought to you by Mercury What gets measured gets managed. And when you're juggling multiple portfolio companies, having a crystal clear measure of cash burn is invaluable. That's why you'll want to keep Mercury's cash burn rate calculator in your toolkit - and pass it along to the founders you're backing. In seconds, you can see how many months of runway remain at a startup's current burn. That kind of clarity can help guide make-or-break decisions around spend, headcount, and future funding rounds. Mercury does banking* differently. They don't stop at banking and financial software to help businesses move money. They help businesses stay two steps ahead with the help of free tools and resources like this . Use the free cash burn rate calculator *Mercury is a financial technology company, not a bank. Banking services provided through Choice Financial Group, Column N.A., and Evolve Bank & Trust; Members FDIC. An Interview with Steve Case To start, I'd love to connect the two eras we're talking about and the lessons we might take from them. How much does the current AI wave remind you of the dotcom bubble? It has some similarities, but some differences, too. Like the internet, AI has been many years in the making. When you look at AI, some of the core technologies can be traced back to something like 70 years ago. This is not a new idea. It just took that time for it to become a mainstream consumer phenomenon. Obviously, over the last ten to twenty years, a lot of companies have integrated AI. Most of the apps we use on our phones rely on AI to some extent. The difference is that nobody called it AI. But it was driving recommendation engines and so on; it was just more of a back-end, invisible thing. It only became an in-your-face visible technology with the success of ChatGPT. That timing dynamic reminds me of the dotcom era. The gold rush mentality does too. People feel that this is the next big thing, and they don't want to miss out, which leads to investors pouring a lot of money into companies. A few of those will be wildly successful, many will be OK, and a good number will also probably end up hitting the wall and going out of business, which is what happened with the internet. Clearly, AI as a core technology and platform is going to have a comparable or greater impact to the internet. It has the ability to transform industries and society in very fundamental ways, but there will be a mix of successes and failures. A final point I'd make is about government and policy. What most people don't appreciate about the internet is that the United States wouldn't have been the leader it was with respect to that technology were it not for a series of government decisions: first, you have the government's decision to fund the Defense Department's ARPANET, which basically became the internet. Next, there was the Justice Department's decision in 1984 to break up AT&T into seven regional operating companies, which drove communication costs down and made the internet much more affordable. Third, there was the decision by the FCC to mandate open access for the telephone networks so that they had to let AOL and others plug into them. And, finally, in the early 90s, Congress passed a law opening up the internet to consumers and businesses. Up until that point, it had been restricted to government agencies and educational institutions. It's easy to forget these things, but if they hadn't happened, the internet would not have evolved the way it did. In the case of AI, it's really important that we figure out what that policy overlay should be. How do you make sure that while the technology is being developed, you don't over-regulate and stifle innovation? Europe has historically made the mistake of focusing too much on what might go wrong and, as a result, stifles what might go right. At the same time, though, because AI is so ubiquitous already (versus the internet, which grew slowly before mass adoption), some engagement, some policy guardrails are necessary now. What might some common-sense guidelines look like? One of the lessons from the internet is that you need to mandate open access. When it comes to AI, I think we need to make sure the big platform companies are essentially required to have open access. We don't want to create a system that just allows the big companies to dominate; we have to force them to open their networks and keep them open for new companies to participate and innovate. You had the rare experience of building what was considered the most significant company of its time during a historic bull market. It remains to be seen to what extent AI is a bubble, but I suspect the lessons you learned building AOL during the dotcom boom are deeply relevant for today's founders. As a jumping-off point, how did you manage your mental game during that period? AOL went from a relatively small company to one of the most important on the planet in a short period of time. The company must have been changing noticeably almost every day. Part of my job was to be a shock absorber for the rest of the company. As the CEO, you have to even out the highs and lows for people. When things are going great, remind them about the risk. I used to call that "delegating paranoia." When things are down in the dumps, remind them of why you have a bright future. There were plenty of moments like that at AOL - we'd be on the cover of a magazine with the headline saying "AOL is going to go under for XYZ reason." It's your role to provide that balance so that people can focus on the overall mission. It probably helped that it took more than a decade for us to get real traction. I joke that AOL was a ten-year-in-the-making overnight success. The time it took us probably gave all of us, including me, more perspective and humility when all of a sudden it was this go-go-go momentum. It helped me not buy into all the positives or all the negatives. Beyond that, you have to surround yourself with good advisors, including board members. They were helpful in making sure we were taking a step back at the right times and not just focusing on the day-to-day so much that we missed something. You have to learn to look at the company not just as a snapshot but as a movie that's playing out. I imagine that one of the biggest challenges of scaling that fast is finding enough great people who understand what you're building, and creating the right structure to get the best out of them. Although AI founders today can probably get more leverage on people than during the 1990s, great talent is still essential. What was your approach to recruiting and organizing talent, and how did it evolve with the business? Well, it definitely evolved. In the early days, when we were just a couple dozen people, it was about surrounding ourselves with true believers. This was before people knew what the internet was, so there weren't that many people interested in it. We were looking for people who wanted to be a part of the journey and could add value to it. When headcount got into the hundreds, we started to be a bit more precise in terms of the roles we needed. You start to run searches for roles and look in a more structured, disciplined way. When we got into the thousands, and things really started accelerating, I realized that as the CEO, I couldn't be involved in everything. And so I needed to shift my mindset to spend the majority of my time on recruiting. It might not have been 50% of my actual hours, but it was more than 50% of my attention . A lot of my job in those days was not just promoting AOL but evangelizing the internet. I'd travel a lot and speak at a lot of conferences - Allen&Co in Sun Valley and others. I always had my radar on: Who's going to be there? Are there people who might be partners in a way that works for us and works for them? Is there anyone I'm really impressed with that I can convince to leave what they're doing and join us? Every meeting I was in, every conference I was attending - whatever it was that I was doing - looking for great people was always on my agenda. With the right people and the right focus, anything is possible. You mentioned that as the company scaled, you felt you couldn't do everything anymore. The pendulum in tech seems to have swung towards CEOs feeling like they should micro-manage more and have their hands on every part of the business. Why did that feel like the wrong fit for you? Read more | N6: https://substackcdn.com/image/fetch/$s_!u9G8!,f_auto,q_auto:good,fl_progressive:steep/https%3A%2F%2Fsubstack-post-media.s3.amazonaws.com%2Fpublic%2Fimages%2F2d820b70-d9eb-4eb1-bf85-7955d4408b07_3742x2839.jpeg | S6: 1 | T6: core | U6: 2026-04-15 06:31:36 | V6: active | W6: 0 | Z6: 0 | AA6: 0 | AC6: 0 | AE6: 0 | AF6: 0 | AG6: 0 | AH6: 0
A7: 미확인 | B7: =IFERROR(INDEX('Source Check'!$A:$A, MATCH(C7, 'Source Check'!$B:$B, 0)), "미등록") | C7: 62 | D7: generalist.com | E7: https://www.generalist.com/ | F7: =IFERROR(INDEX('Source Check'!$E:$E, MATCH(C7, 'Source Check'!$B:$B, 0)), "") | G7: 358 | H7: https://www.generalist.com/p/modern-meditations-immad-akhund | J7: modern meditations immad akhund | L7: Illustration by Eleanor Taylor Friends, How often do you think about the Mongolian Empire? For Mercury CEO, Immad Akhund, the answer seems to be "surprisingly often." For our final interview of the year, I asked the founder of one of my very favorite products to share his latest obsessions, contrarian opinions, and favorite reads. As well as outlining the h… Read more | N7: https://substackcdn.com/image/fetch/$s_!7vOy!,f_auto,q_auto:good,fl_progressive:steep/https%3A%2F%2Fsubstack-post-media.s3.amazonaws.com%2Fpublic%2Fimages%2F788cafb3-056b-46eb-a300-bc7e9ab40996_3857x3000.jpeg | S7: 1 | T7: core | U7: 2026-04-15 06:31:36 | V7: active | W7: 1 | X7: 2026-04-19 | Y7: 2026-04-19 | Z7: 1 | AA7: 0 | AC7: 0 | AE7: 0 | AF7: 0 | AG7: 0 | AH7: 0
A8: 미확인 | B8: =IFERROR(INDEX('Source Check'!$A:$A, MATCH(C8, 'Source Check'!$B:$B, 0)), "미등록") | C8: 62 | D8: generalist.com | E8: https://www.generalist.com/ | F8: =IFERROR(INDEX('Source Check'!$E:$E, MATCH(C8, 'Source Check'!$B:$B, 0)), "") | G8: 357 | H8: https://www.generalist.com/p/what-to-watch-in-2026 | J8: what to watch in 2026 | L8: 🌟 Happy 2026! There's never been a better time to join our premium newsletter and invest in yourself. It's designed to make you a better founder, investor, and technologist. Members get access to the strategies, tactics, and wisdom of exceptional investors and founders. Today's piece is a subscriber-only edition. Friends, The world is not waiting to start the year. In just over a week, we have seen that the world of 2026 will not be the same as that of 2025. Trump's actions in Venezuela are the most naked illustration of this fact, revealing the changing nature of power and shifts in spheres of relative influence. Technology is not immune to such developments, and, indeed, is a key input. Even with January just getting its footing, our sector is in motion: in a span of just a few weeks, Jensen Huang struck a $20 billion deal for Groq's talent and IP, revealed Nvidia's upcoming Rubin architecture, and saw China order its domestic companies to pause purchases of H200 chips. Meanwhile, DeepSeek released research rethinking AI training, ChatGPT launched a dedicated health product, Meta is attempting to purchase Chinese-founded startup Manus, and Anthropic is raising $10 billion at a $350 billion valuation. All of this is happening against the backdrop of growing unease about AI valuations and the possibility that we are in the midst of a rapidly inflating bubble primed to burst. As a reminder: it is January 9th. To try and grasp what (else) 2026 might have in store, particularly with regard to tech and venture capital, I reached out to a collection of more than 45 elite investors and thinkers. I asked each of these people to answer the question: What company, market, or trend do you think is most worth paying attention to in 2026? Below, you will find their answers, organized into seven themes. It includes entries from legends like Reid Hoffman, Kirsten Green, Gili Raanan, and Aydin Senkut, as well as those I consider the sharpest thinkers from the next generation. It is, in a sense, a collection of futures. A cadre of possible paths that may or may not unfurl. In big and little ways, I hope that they make you a little more aware of what may happen and where opportunities might lie. As was the case with last year's edition , I compiled this piece with the express goal of creating something that more than justifies the cost of The Generalist's premium subscription on its basis alone. Given the insights I've gleaned from it already, I believe we've achieved that for anyone who works in venture capital, actively angel invests, or is considering starting a company. I suspect it will also be of great use to operators who want to understand how their respective industries could develop. Here's what to expect: The robotics company helping with data center buildouts A voice AI company poised to come out of stealth The African fintech following Nubank's trajectory Where China is poised to outcompete America A potential landmark in nuclear energy An AI myth gets exposed The startups poised to win in Latin America The under-the-radar search startup used by Cursor To set yourself up for the best possible 2026, join our premium subscription for just $22/month today . It's designed to make you a radically better investor for a teeny fraction of the cost of a traditional investing intelligence service. Subscribe now Again, my hope and goal is that this piece alone repays the cost of a year's subscription. PS. You know this already, but for the avoidance of doubt: this is not investment advice . This is intended to surface new ideas and guide you toward interesting topics. Most submissions focus on private companies, but please heed this, particularly for those that highlight a crypto project with a public token. These tend to be hyper-volatile assets. You should always make investment decisions based on your own research. I. The physical world wakes up AI's most impressive feats have typically occurred on screens. That may be changing. Robots are learning by watching humans, excavators are moving dirt without drivers, and the robotics sector is splitting into two worlds: one of hype, another of quiet deployment. Read more | N8: https://substackcdn.com/image/fetch/$s_!_tEY!,f_auto,q_auto:good,fl_progressive:steep/https%3A%2F%2Fsubstack-post-media.s3.amazonaws.com%2Fpublic%2Fimages%2F1386660d-ee2b-45ca-8daa-9c5c71fbd0f0_2912x1632.png | S8: 1 | T8: core | U8: 2026-04-15 06:31:36 | V8: active | W8: 0 | Z8: 0 | AA8: 0 | AC8: 0 | AE8: 0 | AF8: 0 | AG8: 0 | AH8: 0
A9: 미확인 | B9: =IFERROR(INDEX('Source Check'!$A:$A, MATCH(C9, 'Source Check'!$B:$B, 0)), "미등록") | C9: 62 | D9: generalist.com | E9: https://www.generalist.com/ | F9: =IFERROR(INDEX('Source Check'!$E:$E, MATCH(C9, 'Source Check'!$B:$B, 0)), "") | G9: 356 | H9: https://www.generalist.com/p/nothings-carl-pei-on-building-a-1b-smartphone-company | J9: nothings carl pei on building a 1b smartphone company | L9: "As humans, one of our superpowers is creativity. Both on an individual level, but also on a species level. And by creativity, I mean the ability to solve problems." -Carl Pei Listen or watch now on YouTube , Spotify , or Apple Podcasts Carl Pei is the founder of Nothing, the consumer electronics company known for its distinctive transparent design language across smartphones and audio products. Before launching Nothing in 2020, Carl co-founded OnePlus, where he spent seven years helping build it into a major smartphone brand. But Carl's instincts as a builder showed up much earlier. As a teenager, he taught himself to code by building Pokémon fan sites, all while moving between China, the U.S., and Sweden. That combination of early creation and constant change shaped a founder comfortable with uncertainty-and deeply motivated by questions bigger than products. Carl thinks often about time and mortality, is skeptical of early retirement, and believes creativity is humanity's real advantage. In an industry obsessed with optimization, he's focused on making technology feel meaningful again. In our conversation, we explore: The origins of Nothing's transparent design language and how it helps differentiate the brand in a mature, competitive market Carl's childhood fascination with mortality and how it continues to drive his ambition today Nothing's multiple near-death experiences, from 80% defect rates on first products to fundraising struggles Why India has become a crucial market for Nothing's smartphone business How Nothing approaches community involvement, including letting users invest alongside VCs The company's approach to integrating AI features without overhyping the technology Carl's admiration for Genghis Khan's management style and talent acquisition approach The future of consumer electronics beyond smartphones Thank you to our sponsor, Guru - The AI source of truth for work Explore the episode Timestamps ( 00:00 ) Introduction to Carl Pei and Nothing ( 02:44 ) Nothing's long-term vision ( 06:33 ) How existential thinking shapes Carl's motivation ( 10:12 ) Why Carl's planned sabbatical ended after ten days ( 12:35 ) Carl's international upbringing ( 16:02 ) Entrepreneurial experiments in China ( 19:10 ) Carl's competitive nature and attitude toward school ( 25:30 ) Lessons from seven years at OnePlus ( 28:07 ) Taking a break at age 31 ( 30:50 ) Carl's fundraising strategy ( 33:26 ) Why Carl chose London for Nothing's HQ ( 35:12 ) Lessons from Genghis Khan ( 38:38 ) Nothing's first near-death moment ( 42:56 ) Nothing's product evolution and breakout hits ( 45:24 ) Partnering with Teenage Engineering ( 49:28 ) Design inspirations ( 51:36 ) How Nothing recruits talent ( 53:42 ) Nothing's approach to marketing ( 56:51 ) How India became a key market ( 59:48 ) Why Nothing created CMF ( 1:02:12 ) Why Carl is bullish on India ( 1:03:32 ) How Carl thinks about AI ( 1:07:05 ) Rethinking ads based on community feedback ( 1:09:05 ) How Nothing leverages community ( 1:11:23 ) Why AI hardware is struggling ( 1:13:37 ) Carl's thoughts on the future of consumer electronics ( 1:15:10 ) Philosophies that shape Carl's worldview ( 1:16:45 ) Final meditations Follow Carl Pei LinkedIn: X: Resources and episode mentions Books Apple in China: The Capture of the World's Greatest Company : Conqueror (5 book series): Zen Mind, Beginner's Mind: Informal Talks on Zen Meditation and Practice : People Genghis Khan: Elon Musk on X: Jesper Kouthoofd on LinkedIn: Charlie Smith on LinkedIn: Other resources Nothing: Carl's AMA thread on X: Steve Jobs' 2005 Stanford Commencement Address: Naruto: League of Legends : OnePlus: King: Klarna: Ear (1): Teenage Engineering: Dior: Gucci: Ipren the Intelligent Painkiller: Get to Know Creative Museum Tokyo ‐ Experience the Creativity of Diverse Works and Creators in an Expansive Space Presented by Sony: 2001: A Space Odyssey : HAL 9000: Loewe: 4K Restoration: 1984 Super Bowl APPLE MACINTOSH Ad by Ridley Scott: CMF: Essential apps: Porsche: Humane: Limitless: Rabbit: Friend: Subscribe to the show I'd love it if you'd subscribe and share the show. Your support makes all the difference as we try to bring more curious minds into the conversation. YouTube Spotify Apple Production and marketing by penname.co . For inquiries about sponsoring the podcast, email jordan@penname.co. | N9: https://substackcdn.com/image/fetch/$s_!uKI7!,w_1456,c_limit,f_auto,q_auto:good,fl_progressive:steep/https%3A%2F%2Fsubstack-post-media.s3.amazonaws.com%2Fpublic%2Fimages%2F1200e4c5-5be5-451c-a20e-657f4e576886_475x151.png | S9: 1 | T9: core | U9: 2026-04-15 06:31:36 | V9: active | W9: 0 | Z9: 0 | AA9: 0 | AC9: 0 | AE9: 0 | AF9: 0 | AG9: 0 | AH9: 0
A10: 미확인 | B10: =IFERROR(INDEX('Source Check'!$A:$A, MATCH(C10, 'Source Check'!$B:$B, 0)), "미등록") | C10: 62 | D10: generalist.com | E10: https://www.generalist.com/ | F10: =IFERROR(INDEX('Source Check'!$E:$E, MATCH(C10, 'Source Check'!$B:$B, 0)), "") | G10: 355 | H10: https://www.generalist.com/p/programming-sunlight-ben-nowack | J10: programming sunlight ben nowack | L10: "It's either sunny or it's not sunny, and there's not much you can do about that-but we're trying to change that for the first time ever." -Ben Nowack Listen or watch now on YouTube , Spotify , or Apple Podcasts Most energy conversations start with scarcity. This one starts with abundance. Sunlight powers nearly everything on Earth, directly or indirectly. And yet we have almost no control over when or where we get it. Ben Nowack thinks that's a solvable problem. Ben is the founder and CEO of Reflect Orbital, a company building satellites designed to redirect sunlight from space-not as a thought experiment, but as a product. The company nearly died before it worked. Eight months in, Ben had $300 left and was living in a garage. He made a deliberate decision to go $50,000 into credit card debt to finish critical tests. At one point, he was down to $21 of available credit. A month later, Reflect raised its first round. Today, the company is preparing to launch its first revenue-generating satellites. This is a conversation about building conviction, finding the real market, and what changes when a fundamental resource becomes programmable. In our conversation, we explore: How Reflect's satellites work The surprising pivot from energy to lighting applications that made the business immediately viable Ben's remarkable journey from building RC planes and X-ray machines in high school to founding Reflect Why previous attempts at space mirrors failed and what's changed to make this possible now The near-death moment when Ben went $50,000 into credit card debt to keep his vision alive How Reflect plans to scale from moonlight-level brightness to potentially powering solar farms The company's first satellite launches planned for this year, and their path to a full constellation The wide range of applications, from emergency response to municipal lighting to agriculture Explore the episode Timestamps ( 00:00 ) Introduction to Ben Nowack ( 02:26 ) What Reflect Orbital is building ( 05:07 ) How the satellite constellation works ( 08:00 ) What Reflect is launching this year ( 10:35 ) Finding early markets ( 13:43 ) Ben's childhood and early building experiences ( 22:04 ) What Ben learned working for startups ( 28:03 ) High school projects: X-ray machines, rocket engines, and fusion reactors ( 33:14 ) The eureka moment that led to Reflect ( 35:24 ) Early validation of the idea ( 38:35 ) The Russian space mirror experiments of the 1990s and what's changed ( 42:31 ) Partnering with Tristan Similac as co-founder ( 45:05 ) Baiju Bhatt's involvement ( 47:04 ) Why Reflect isn't pivoting to space-based data centers ( 50:54 ) Common misconceptions about Reflect's technology ( 55:11 ) Why programmable light is valuable ( 1:01:28 ) Initial target markets ( 1:03:42 ) The future markets for Reflect ( 1:07:33 ) Reflect's company culture and operational philosophy ( 1:12:05 ) Surprises and struggles in building Reflect ( 1:14:56 ) Putting the idea to the test Follow Ben Nowack LinkedIn: X: Resources and episode mentions People Vladimir Syromyatnikov: Tristan Semmelhack on LinkedIn: Baiju Bhatt on LinkedIn: Marc Andreessen on X: J.P. Morgan: Ric Burton on LinkedIn: Other resources Reflect Orbital: Zipline: Cassegrain: Advanced Composite Solar Sail System (ACS3): Znamya: Aetherflux: Elon Musk's post on X about building a sentient sun: Denali: Subscribe to the show I'd love it if you'd subscribe and share the show. Your support makes all the difference as we try to bring more curious minds into the conversation. YouTube Spotify Apple Production and marketing by penname.co . For inquiries about sponsoring the podcast, email jordan@penname.co. | N10: https://substackcdn.com/image/fetch/$s_!WSAh!,w_1200,h_600,c_fill,f_jpg,q_auto:good,fl_progressive:steep,g_auto/https%3A%2F%2Fsubstack-post-media.s3.amazonaws.com%2Fpublic%2Fimages%2F6029b0cd-09a3-40cb-a969-8ffe50a1acd8_1456x1048.png | S10: 1 | T10: core | U10: 2026-04-15 06:31:36 | V10: active | W10: 0 | Z10: 0 | AA10: 0 | AC10: 0 | AE10: 0 | AF10: 0 | AG10: 0 | AH10: 0
A11: 미확인 | B11: =IFERROR(INDEX('Source Check'!$A:$A, MATCH(C11, 'Source Check'!$B:$B, 0)), "미등록") | C11: 62 | D11: generalist.com | E11: https://www.generalist.com/ | F11: =IFERROR(INDEX('Source Check'!$E:$E, MATCH(C11, 'Source Check'!$B:$B, 0)), "") | G11: 354 | H11: https://www.generalist.com/p/productivity-stack-2026 | J11: productivity stack 2026 | L11: Friends, Last January, on a whim, I shared a few of the productivity methods I've found effective in maximizing my output while building The Generalist. It was driven by a geekish obsession with tiny optimizations, a love for adopting niche tools, and a real belief that the environment you make for yourself impacts the work you are capable of. To my surprise, it became one of The Generalist's most popular pieces. With January in full swing and the year still stretching in front of us, I decided to sit down and outline the new tools and methods I've found effective over the past year. It turned into quite a collection. You'll find 26 tools I recommend (both digital and analog) and 8 practices I've found invaluable. I've avoided repeating last year's recommendations (though I still use them), so if you're as into these kinds of hacks and optimizations as I am, you may want to read that piece, too. Tools An exhaustive list of the programs, apps, extensions, and physical objects I recommend. Read more | N11: https://substackcdn.com/image/fetch/$s_!JaEN!,f_auto,q_auto:good,fl_progressive:steep/https%3A%2F%2Fsubstack-post-media.s3.amazonaws.com%2Fpublic%2Fimages%2Fcc7ae492-fcba-4478-8503-59caaf59f5b1_2912x1632.png | S11: 1 | T11: core | U11: 2026-04-15 06:31:36 | V11: active | W11: 0 | Z11: 0 | AA11: 0 | AC11: 0 | AE11: 0 | AF11: 0 | AG11: 0 | AH11: 0
A12: 미확인 | B12: =IFERROR(INDEX('Source Check'!$A:$A, MATCH(C12, 'Source Check'!$B:$B, 0)), "미등록") | C12: 62 | D12: generalist.com | E12: https://www.generalist.com/ | F12: =IFERROR(INDEX('Source Check'!$E:$E, MATCH(C12, 'Source Check'!$B:$B, 0)), "") | G12: 353 | H12: https://www.generalist.com/p/the-private-company-bringing-nuclear | J12: the private company bringing nuclear | L12: "We [the U.S.] went from controlling something like 86% of global enrichment capacity to effectively last place." Listen or watch now on YouTube , Spotify , or Apple Podcasts Roughly 20% of the U.S. power grid runs on nuclear energy. A quarter of the fuel behind it is headed toward a hard stop. In this episode, I sit down with Scott Nolan , founder and CEO of General Matter, to unpack why uranium enrichment has quietly become one of the most consequential industrial bottlenecks of the 21st century. While at Founders Fund, Scott spent over a year searching for an American enrichment company to back. When he couldn't find one, he decided to build it himself. Less than a year after emerging from stealth, General Matter secured a historic enrichment site in Paducah, Kentucky, and was awarded a $900 million Department of Energy contract-marking one of the first serious efforts to rebuild domestic enrichment capacity ahead of the 2028 ban on Russian supply. In this episode, we discuss: Why enrichment is the missing link in America's nuclear supply chain How the U.S. went from controlling 86% of global enrichment capacity to effectively none at commercial scale The science behind uranium enrichment and why it matters for next-generation reactors Why Scott applied the SpaceX playbook to nuclear after more than a decade in venture capital How General Matter is revitalizing the historic Paducah, Kentucky enrichment site The significance of General Matter's $900 million Department of Energy contract The bipartisan political support for expanding nuclear energy Why Scott believes nuclear energy could grow 3-4x by 2050 The parallels between America's space and nuclear industries Thank you to our sponsor, Persona : Trusted identity verification for any use case. Explore the episode Timestamps ( 00:00 ) Introduction to Scott Nolan ( 02:24 ) General Matter's mission to rebuild U.S. enrichment ( 05:08 ) How the U.S. lost its edge ( 06:24 ) The nuclear fuel cycle explained-and where enrichment fits ( 08:31 ) Scott's background: From SpaceX and Founders Fund to General Matter ( 13:56 ) Lessons from SpaceX ( 17:50 ) How Scott's focus evolved over 13 years at Founders Fund ( 21:00 ) How Scott landed on nuclear enrichment ( 25:58 ) Why nuclear energy was off the radar-until recently ( 30:10 ) Finding the right partner: Scott and Lee's collaboration ( 32:04 ) What downblending means and why it matters ( 33:30 ) How U.S. uranium enrichment quietly came to an end ( 38:34 ) The Russian uranium ban and the 2028 supply cliff ( 40:38 ) How General Matter plans to compete ( 43:09 ) Building a world-class team ( 46:03 ) The market for enriched uranium ( 49:30 ) Future bottlenecks ( 50:56 ) What the U.S. needs to actually scale nuclear energy ( 51:32 ) Uranium supply constraints ( 54:16 ) LEU vs. HALEU: the fuels powering old and new reactors ( 57:49 ) Why 20% enrichment is a critical threshold ( 59:30 ) Why General Matter chose Paducah, Kentucky ( 01:04:35 ) Legislation and executive orders easing nuclear friction ( 01:07:06 ) The $900 million Department of Energy award ( 01:11:08 ) Why mission matters most ( 01:14:12 ) Final meditations Follow Scott Nolan X: Resources and episode mentions Books Zero to One: Notes on Startups, or How to Build the Future : People Peter Thiel on X: Lee Robinson on LinkedIn; Other resources No Rivals: The Prophet (Part I): General Matter: Founders Fund: SpaceX: How Anduril Is Reimagining the Defense Industry: Faster Tech, Ethical AI, and a New Kind of Deterrence (Trae Stephens, Co-Founder & Executive Chairman at Anduril): The Boring Company: Neuralink: Nubank: Radiant: Megatons to Megawatts Program: S.1111 - ADVANCE Act of 2023: Subscribe to the show I'd love it if you'd subscribe and share the show. Your support makes all the difference as we try to bring more curious minds into the conversation. YouTube Spotify Apple Production and marketing by penname.co . For inquiries about sponsoring the podcast, email jordan@penname.co. | N12: https://substackcdn.com/image/fetch/$s_!lmo-!,w_1456,c_limit,f_auto,q_auto:good,fl_progressive:steep/https%3A%2F%2Fsubstack-post-media.s3.amazonaws.com%2Fpublic%2Fimages%2F6902c32a-356e-4652-bb15-25b769f0fa80_451x127.png | S12: 1 | T12: core | U12: 2026-04-15 06:31:36 | V12: active | W12: 0 | Z12: 0 | AA12: 0 | AC12: 0 | AE12: 0 | AF12: 0 | AG12: 0 | AH12: 0
A13: 미확인 | B13: =IFERROR(INDEX('Source Check'!$A:$A, MATCH(C13, 'Source Check'!$B:$B, 0)), "미등록") | C13: 62 | D13: generalist.com | E13: https://www.generalist.com/ | F13: =IFERROR(INDEX('Source Check'!$E:$E, MATCH(C13, 'Source Check'!$B:$B, 0)), "") | G13: 352 | H13: https://www.generalist.com/p/lessons-of-a-first-time-fund-manager | J13: lessons of a first time fund manager | L13: Friends, Four years ago, I set out to raise my first venture fund. The result was Generalist Capital, a $15 million vehicle to invest in a small collection of (hopefully) legendary companies. The beginning of this year marks something of a turning point. After closing on a few investments, Generalist Capital officially moved from the deployment phase to management and harvesting. That makes it a fitting moment to share the lessons learned along the way. Though venture capital is awash in content, in my view, there's too little introspective writing on the mental game of fund management. Below, you'll find my attempt to distill the most important lessons I've learned so far. To that end, these are best seen as the lessons of a first-time fund manager, relating primarily to the challenges of starting a fund and establishing an initial viable strategy. Naturally, the gravity of these lessons will depend on information I cannot give you: my long-term performance as an investor. It will likely take another six to ten years to discover how promising a portfolio I have built with Generalist Capital, and even longer to know definitively if I am any good. As of our last update to LPs, Generalist Capital was performing in the top 10-15% in its vintage, but the data suggests that it takes about six years for a fund to settle into its terminal quartile. There's still a long way left to run and too much uncertainty to read much into this. I am afraid that this is the best I can offer you. Let this serve as a reminder, then, if any were needed, that you should take my lessons with a grain of salt. I have achieved little, and every investor must learn to play their own game. Though I hope they spark new ideas for you, these are just the observations of one manager at the beginning of what I hope proves to be a long career. If this is your first time managing a fund, be extremely skeptical of your early investment urges. You're probably overly keen to validate your existence to your LPs. The best companies can go under the radar for a long time. When other VCs asked which of my investments I was most bullish about, I told them freely. It still took several years for a Tier 1 firm to lead a round into the company. You do not have to wait for a round. If you have enough to offer a company, they'll find a way to bring you aboard ahead of a formal raise. When you see a startup you love, try to make something happen. Don't assume you know your level. New managers often think they can't get access to rounds led by Tier 1 VCs. With the right pitch, you may be closer than you think. It's very rare you see everything you want in a startup: founder, market, traction, and so on. When you do, write a much bigger check than you ordinarily would. The first investor has a unique relationship with a founder. You can build good relationships no matter when you invest, but the first check in earns a special level of trust. Contrary to what you might expect, the best companies are not easier to access as round sizes grow. Competition escalates as they succeed, often through late growth. The best investors often need little more than a sentence to explain why they've invested in a company. The longer and more convoluted your investment rationale is, the more skeptical you should be of it. Find your pace. A generation of managers has been conditioned to deploy vintages in 18-24 months. There is nothing wrong with taking twice as long, or more. Just because a deal is hot does not mean it is good. Don't let other people's urgency influence your desire. Remind yourself: the best venture firms in the world make a majority of bad investments. Don't index on a buzzy name. Conversely, if some of the best investors in the world are backing a startup you don't consider promising, look again, extremely closely. There's a good chance you're missing something important. Remember, the best investors in the world ≠ the best known investors. Calibrate accordingly. Don't assume the best opportunities will land in your lap. Outbound sourcing is a necessity. Progress is never linear. A company that you had more or less written off can suddenly catch light, and one that was on a breakout trajectory can easily stall or stumble. Don't push your anxiety onto your founders. It's not your job to let them know of every new company that pops up in their space. If you're asked for advice, give it honestly, but recognize that you have 0.01% of the context a founder has. Fight for every dollar. Getting an extra $10K into a breakout company can make a huge difference for a small fund. Founders respond to conviction. Earnestly explaining to an entrepreneur why you're excited about their business and showing a desire to move quickly can overcome any number of natural disadvantages. Be skeptical of a pitch that looks too rational. Great companies often have something paradoxical about them. If something doesn't quite make sense, that's a good indication you should lean in, not out. Be careful you don't get stuck correcting your last mistake. If you invested too little in a startup that has just started to break out, don't triple the size of your next check to compensate. Consider each opportunity anew. If you're not positioned to catch a wave, don't chase it. You could burn an entire vintage on second-and third-rate AI companies. Read more | N13: https://substackcdn.com/image/fetch/$s_!MTsx!,f_auto,q_auto:good,fl_progressive:steep/https%3A%2F%2Fsubstack-post-media.s3.amazonaws.com%2Fpublic%2Fimages%2F2994d4f1-bacf-44ba-987b-61056318dd88_2688x1792.jpeg | S13: 1 | T13: core | U13: 2026-04-15 06:31:36 | V13: active | W13: 0 | Z13: 0 | AA13: 0 | AC13: 0 | AE13: 0 | AF13: 0 | AG13: 0 | AH13: 0
A14: 미확인 | B14: =IFERROR(INDEX('Source Check'!$A:$A, MATCH(C14, 'Source Check'!$B:$B, 0)), "미등록") | C14: 62 | D14: generalist.com | E14: https://www.generalist.com/ | F14: =IFERROR(INDEX('Source Check'!$E:$E, MATCH(C14, 'Source Check'!$B:$B, 0)), "") | G14: 351 | H14: https://www.generalist.com/p/how-bolt-survived-an-85-revenue-crash | J14: how bolt survived an 85 revenue crash | L14: "We don't care that we're from a small country. We've always had the view that if we work harder and [make] smarter decisions, we can beat [any] company in the world, regardless of how big they are." Listen or watch now on YouTube , Spotify , or Apple Podcasts In 2013, on an Estonian island of just 10,000 residents, a teenager borrowed €5,000 from his parents and decided to take on Uber. Twelve years later, Markus Villig leads Bolt , a company operating in 50+ countries, generating nearly €3 billion in revenue, and standing as one of the only European tech companies competing at true global scale. Rather than going head-to-head with incumbents in their strongest markets, Bolt expanded through underserved cities, emerging economies, and overlooked segments of urban transport. When COVID erased 85% of its revenue in weeks, the company didn't retreat; it staged a kind of corporate "eucatastrophe," pivoting into food delivery across nearly 20 countries in what became a company-wide sprint. That same bias toward action now shapes Markus's broader agenda: investing in defense tech for Estonia and Ukraine, pushing for capital markets reform, and advancing a contrarian thesis on autonomous vehicles. In this conversation, we discuss: How growing up in Soviet-occupied Estonia shaped Markus's ambition and moral clarity How Bolt's European ethos and long-term focus on driver retention became a structural advantage The marketplace models and capital discipline that allowed Bolt to outmaneuver better-funded rivals Why Bolt found breakout success in African markets after failing in 12 Western countries The 85% revenue collapse during COVID and the rapid food delivery pivot that reshaped the company Bolt's partnerships with Stellantis and Pony.ai and its long-term bet on autonomous vehicles Why Ukrainian and Eastern European startups are often outperforming their Western peers Markus's blueprint for closing Europe's tech deficit and building globally competitive companies Thank you to the partners who make this possible Granola : The app that might actually make you love meetings Brex : The intelligent finance platform. Persona : Trusted identity verification for any use case. Explore the episode Timestamps ( 00:00 ) Intro ( 03:32 ) How The Lord of the Rings shaped Markus's worldview ( 05:52 ) Bolt's underdog story and its existential turning point ( 10:22 ) Estonia's startup DNA and its imprint on Bolt ( 13:38 ) Europe's ambition problem ( 17:23 ) Europe's defense tech gap ( 23:09 ) The need for capital market reform in Europe ( 25:13 ) Bolt's origin story ( 36:35 ) Frugality as strategy ( 38:24 ) What running Bolt actually demands ( 41:27 ) The hidden costs of being too lean ( 42:50 ) Bolt's shift to experimentation ( 44:10 ) Bolt's micromobility strategy ( 45:50 ) How Bolt found the right markets ( 50:44 ) The Serbian mob story ( 54:00 ) Markus on venture capital and lessons from Klarna's board ( 55:40 ) Why Bolt never sold ( 57:08 ) Bolt's autonomous vehicle (AV) strategy and key partnerships ( 1:05:50 ) The concept of culture-market fit ( 1:07:48 ) How Bolt operates: writing, hiring, reading, and more ( 1:13:15 ) Markus's personal strengths ( 1:14:15 ) What people get wrong about business ( 1:16:27 ) Final meditations Follow Markus Villig X: LinkedIn: Resources and episode mentions Books The Lord of the Rings : High Output Management : The Precipice: Existential Risk and the Future of Humanity : People Martin Villig on LinkedIn: Oliver Leisalu on LinkedIn: Jeff Bezos on X: Jensen Huang on LinkedIn: Andy Grove: Other resources Bolt: Palmer Luckey's post on X about Lord of the Rings : Skype: Markus's post on X about Europe lagging in tech: Revolut: Wise: Klarna: Sequoia: Daimler: Stellantis: Pony AI: Waymo: TSMC: Existential Risk and the Future of Humanity: Lessons from AI, Pandemics, and Nuclear Threats (Toby Ord, Author of "The Precipice"): Subscribe to the show I'd love it if you'd subscribe and share the show. Your support makes all the difference as we try to bring more curious minds into the conversation. YouTube Spotify Apple Production and marketing by penname.co . For inquiries about sponsoring the podcast, email jordan@penname.co. | N14: https://substackcdn.com/image/fetch/$s_!pAew!,w_1456,c_limit,f_auto,q_auto:good,fl_progressive:steep/https%3A%2F%2Fsubstack-post-media.s3.amazonaws.com%2Fpublic%2Fimages%2F81215a3c-be4c-42ec-bfe9-8d4c14f50935_1600x128.png | S14: 1 | T14: core | U14: 2026-04-15 06:31:36 | V14: active | W14: 0 | Z14: 0 | AA14: 0 | AC14: 0 | AE14: 0 | AF14: 0 | AG14: 0 | AH14: 0
